Workbook

Sheet mögliche Struktur
A1: öffentlicher Leistungskatalog | I1: Quelleninformation zum internen Gebrauch
N2: in EBM Kalkulationszeit | O2: in EBM Prüfzeit
A3: RM ID | B3: DA | C3: Abschnitt | D3: Unterabschnitt | E3: Leistung | F3: Wert | G3: Bezugsgröße | H3: Bestimmungen | I3: Quelle | J3: Quellenabschnitt | K3: Quellenunterabschnitt | L3: QuellenID | M3: QuellenLeistung | N3: Quellenwert 1 | O3: Quellenwert 2 | P3: Bemerkung
B4: ÄD | I4: GOÄ (GOB) | J4: ='GOÄ-ÄD'!F2 -> B. Grundleistungen und allgemeine Leistungen | K4: ='GOÄ-ÄD'!G2 -> I. Allgemeine Beratungen und Untersuchungen | L4: ='GOÄ-ÄD'!A2 -> 2 | M4: ='GOÄ-ÄD'!B2 -> Ausstellung von Wiederholungsrezepten und/oder Überweisungen | N4: ='GOÄ-ÄD'!C2 -> 2 | P4: ='GOÄ-ÄD'!I2 -> 0
B5: ÄD | I5: GOÄ (GOB) | J5: ='GOÄ-ÄD'!F3 -> B. Grundleistungen und allgemeine Leistungen | K5: ='GOÄ-ÄD'!G3 -> I. Allgemeine Beratungen und Untersuchungen | L5: ='GOÄ-ÄD'!A3 -> 3 | M5: ='GOÄ-ÄD'!B3 -> Eingehende, das gewöhnliche Maß übersteigende Beratung | N5: ='GOÄ-ÄD'!C3 -> 12 | P5: ='GOÄ-ÄD'!I3 -> 0
B6: ÄD | I6: GOÄ (GOB) | J6: ='GOÄ-ÄD'!F4 -> B. Grundleistungen und allgemeine Leistungen | K6: ='GOÄ-ÄD'!G4 -> I. Allgemeine Beratungen und Untersuchungen | L6: ='GOÄ-ÄD'!A4 -> 4 | M6: ='GOÄ-ÄD'!B4 -> Erhebung der Fremdanamnese über einen Kranken | N6: ='GOÄ-ÄD'!C4 -> 14 | P6: ='GOÄ-ÄD'!I4 -> 0
B7: ÄD | I7: GOÄ (GOB) | J7: ='GOÄ-ÄD'!F5 -> B. Grundleistungen und allgemeine Leistungen | K7: ='GOÄ-ÄD'!G5 -> I. Allgemeine Beratungen und Untersuchungen | L7: ='GOÄ-ÄD'!A5 -> 5 | M7: ='GOÄ-ÄD'!B5 -> Ambulante Untersuchung | N7: ='GOÄ-ÄD'!C5 -> 15 | P7: ='GOÄ-ÄD'!I5 -> 0
B8: ÄD | I8: GOÄ (GOB) | J8: ='GOÄ-ÄD'!F6 -> B. Grundleistungen und allgemeine Leistungen | K8: ='GOÄ-ÄD'!G6 -> I. Allgemeine Beratungen und Untersuchungen | L8: ='GOÄ-ÄD'!A6 -> 8 | M8: ='GOÄ-ÄD'!B6 -> Körperliche Untersuchung | N8: ='GOÄ-ÄD'!C6 -> 20 | P8: ='GOÄ-ÄD'!I6 -> 0
B9: ÄD | I9: GOÄ (GOB) | J9: ='GOÄ-ÄD'!F7 -> B. Grundleistungen und allgemeine Leistungen | K9: ='GOÄ-ÄD'!G7 -> I. Allgemeine Beratungen und Untersuchungen | L9: ='GOÄ-ÄD'!A7 -> 11 | M9: ='GOÄ-ÄD'!B7 -> Digitaluntersuchung Darm | N9: ='GOÄ-ÄD'!C7 -> 4 | P9: ='GOÄ-ÄD'!I7 -> 0
B10: ÄD | I10: GOÄ (GOB) | J10: ='GOÄ-ÄD'!F8 -> B. Grundleistungen und allgemeine Leistungen | K10: ='GOÄ-ÄD'!G8 -> I. Allgemeine Beratungen und Untersuchungen | L10: ='GOÄ-ÄD'!A8 -> 15 | M10: ='GOÄ-ÄD'!B8 -> Einleitung und Koordination flankierender therapeutischer und sozialer Maßnahmen | N10: ='GOÄ-ÄD'!C8 -> 15 | P10: ='GOÄ-ÄD'!I8 -> 0
B11: ÄD | I11: GOÄ (GOB) | J11: ='GOÄ-ÄD'!F9 -> B. Grundleistungen und allgemeine Leistungen | K11: ='GOÄ-ÄD'!G9 -> II. Zuschläge zu Beratungen und Untersuchungen nach Nummer 1, 3, 4, 5, 6, 7 oder 8 | L11: ='GOÄ-ÄD'!A9 -> 27 | M11: ='GOÄ-ÄD'!B9 -> Untersuchung einer Frau zur Früherkennung von Krebserkrankungen | N11: ='GOÄ-ÄD'!C9 -> 26 | P11: ='GOÄ-ÄD'!I9 -> Die Zuschläge nach den Buchstaben A bis D sowie K 1 sind nur mit dem einfachen Gebührensatz berechnungsfähig. Sie dürfen unabhängig von der Anzahl und Kombination der erbrachten Leistungen je Inanspruchnahme des Arztes nur einmal berechnet werden. Neben den Zuschlägen nach den Buchstaben A bis
B12: ÄD | I12: GOÄ (GOB) | J12: ='GOÄ-ÄD'!F10 -> B. Grundleistungen und allgemeine Leistungen | K12: ='GOÄ-ÄD'!G10 -> II. Zuschläge zu Beratungen und Untersuchungen nach Nummer 1, 3, 4, 5, 6, 7 oder 8 | L12: ='GOÄ-ÄD'!A10 -> 28 | M12: ='GOÄ-ÄD'!B10 -> Untersuchung eines Mannes zur Früherkennung von Krebserkrankungen | N12: ='GOÄ-ÄD'!C10 -> 18 | P12: ='GOÄ-ÄD'!I10 -> Die Zuschläge nach den Buchstaben A bis D sowie K 1 sind nur mit dem einfachen Gebührensatz berechnungsfähig. Sie dürfen unabhängig von der Anzahl und Kombination der erbrachten Leistungen je Inanspruchnahme des Arztes nur einmal berechnet werden. Neben den Zuschlägen nach den Buchstaben A bis
B13: ÄD | I13: GOÄ (GOB) | J13: ='GOÄ-ÄD'!F11 -> B. Grundleistungen und allgemeine Leistungen | K13: ='GOÄ-ÄD'!G11 -> II. Zuschläge zu Beratungen und Untersuchungen nach Nummer 1, 3, 4, 5, 6, 7 oder 8 | L13: ='GOÄ-ÄD'!A11 -> 34 | M13: ='GOÄ-ÄD'!B11 -> Erörterung (Dauer min. 20 Minuten) der Auswirkung einer Krankheit | N13: ='GOÄ-ÄD'!C11 -> 20 | P13: ='GOÄ-ÄD'!I11 -> Die Zuschläge nach den Buchstaben A bis D sowie K 1 sind nur mit dem einfachen Gebührensatz berechnungsfähig. Sie dürfen unabhängig von der Anzahl und Kombination der erbrachten Leistungen je Inanspruchnahme des Arztes nur einmal berechnet werden. Neben den Zuschlägen nach den Buchstaben A bis
B14: ÄD | I14: GOÄ (GOB) | J14: ='GOÄ-ÄD'!F12 -> B. Grundleistungen und allgemeine Leistungen | K14: ='GOÄ-ÄD'!G12 -> IV. Visiten, Konsiliartätigkeit, Besuche, Assistenz | L14: ='GOÄ-ÄD'!A12 -> 60 | M14: ='GOÄ-ÄD'!B12 -> Konsiliarische Erörterung zwischen zwei oder mehr Ärzten | N14: ='GOÄ-ÄD'!C12 -> 10 | P14: ='GOÄ-ÄD'!I12 -> 0
B15: ÄD | I15: GOÄ (GOB) | J15: ='GOÄ-ÄD'!F13 -> B. Grundleistungen und allgemeine Leistungen | K15: ='GOÄ-ÄD'!G13 -> VI. Berichte, Briefe | L15: ='GOÄ-ÄD'!A13 -> 70 | M15: ='GOÄ-ÄD'!B13 -> Kurze Bescheinigung | N15: ='GOÄ-ÄD'!C13 -> 1 | P15: ='GOÄ-ÄD'!I13 -> 0
... B630: ÄD | I630: GOÄ (GOB) | J630: ='GOÄ-ÄD'!F628 -> #N/A | K630: ='GOÄ-ÄD'!G628 -> #N/A | L630: ='GOÄ-ÄD'!A628 -> A888 | M630: ='GOÄ-ÄD'!B628 -> Psychiatrische Behandlung zur Reintegration eines Erwachsenen als Gruppenbehandlung | N630: ='GOÄ-ÄD'!C628 -> 12 | P630: ='GOÄ-ÄD'!I628 -> #N/A
B631: nÄD | I631: GOÄ (GOB) nÄD | J631: ='GOÄ-nÄD'!E2 -> Beratung - auch mittels Fernsprecher - | K631: ='GOÄ-nÄD'!G2 -> I. Allgemeine Beratungen und Untersuchungen | L631: ='GOÄ-nÄD'!A2 -> 1 | M631: ='GOÄ-nÄD'!B2 -> Angehörigenberatung | N631: ='GOÄ-nÄD'!C2 -> 30 | P631: ='GOÄ-nÄD'!I2 -> 0
B632: nÄD | I632: GOÄ (GOB) nÄD | J632: ='GOÄ-nÄD'!E3 -> Ausstellung von Wiederholungsrezepten und/oder Überweisungen und/ oder Übermittlung von Befunden oder ärztlichen Anordnungen - auch mittels Fernsprecher - durch die Arzthelferin und/oder Messung von Körperzuständen (z.B. Blutdruck, Temperatur) ohne Beratung, bei einer Inanspruchnahme des Arztes | K632: ='GOÄ-nÄD'!G3 -> I. Allgemeine Beratungen und Untersuchungen | L632: ='GOÄ-nÄD'!A3 -> 2 | M632: ='GOÄ-nÄD'!B3 -> Ausstellung von Wiederholungsrezepten und/oder Überweisungen | N632: ='GOÄ-nÄD'!C3 -> 2 | P632: ='GOÄ-nÄD'!I3 -> 0
B633: nÄD | I633: GOÄ (GOB) nÄD | J633: ='GOÄ-nÄD'!E4 -> Untersuchung zur Erhebung des Ganzkörperstatus, gegebenenfalls einschließlich Dokumentation | K633: ='GOÄ-nÄD'!G4 -> I. Allgemeine Beratungen und Untersuchungen | L633: ='GOÄ-nÄD'!A4 -> 8 | M633: ='GOÄ-nÄD'!B4 -> Körperliche Untersuchung | N633: ='GOÄ-nÄD'!C4 -> 12.5 | P633: ='GOÄ-nÄD'!I4 -> 0
B634: nÄD | I634: GOÄ (GOB) nÄD | J634: ='GOÄ-nÄD'!E5 -> Digitaluntersuchung des Mastdarms und/oder der Prostata | K634: ='GOÄ-nÄD'!G5 -> I. Allgemeine Beratungen und Untersuchungen | L634: ='GOÄ-nÄD'!A5 -> 11 | M634: ='GOÄ-nÄD'!B5 -> Digitaluntersuchung Darm | N634: ='GOÄ-nÄD'!C5 -> 5 | P634: ='GOÄ-nÄD'!I5 -> 0
B635: nÄD | I635: GOÄ (GOB) nÄD | J635: ='GOÄ-nÄD'!E6 -> Strukturierte Schulung einer Einzelperson mit einer Mindestdauer von 20 Minuten (bei Diabetes, Gestationsdiabetes oder Zustand nach Pankreatektomie) - einschließlich Evaluation zur Qualitätssicherung unter diabetologischen Gesichtspunkten zum Erlernen und Umsetzen des Behandlungsmanagements, einschließlich der Auswertung eines standardisierten Fragebogens - | K635: ='GOÄ-nÄD'!G6 -> II. Zuschläge zu Beratungen und Untersuchungen nach Nummer 1, 3, 4, 5, 6, 7 oder 8 | L635: ='GOÄ-nÄD'!A6 -> 33 | M635: ='GOÄ-nÄD'!B6 -> Strukturierte Schulung einer Einzelperson mit einer Mindestdauer von 20 Min. (bei Diabetes, Gestationsdiabetes oder Zustand nach Pankrea- tektomie) - einschl. Evaluation zur Qualitätssicherung | N635: ='GOÄ-nÄD'!C6 -> 20 | P635: ='GOÄ-nÄD'!I6 -> Die Zuschläge nach den Buchstaben A bis D sowie K 1 sind nur mit dem einfachen Gebührensatz berechnungsfähig. Sie dürfen unabhängig von der Anzahl und Kombination der erbrachten Leistungen je Inanspruchnahme des Arztes nur einmal berechnet werden. Neben den Zuschlägen nach den Buchstaben A bis
B636: nÄD | I636: GOÄ (GOB) nÄD | J636: ='GOÄ-nÄD'!E7 -> Ausführlicher schriftlicher Krankheits- und Befundbericht (einschließlich Angaben zur Anamnese, zu dem(n) Befund(en), zur epikritischen Bewertung und gegebenenfalls zur Therapie) | K636: ='GOÄ-nÄD'!G7 -> VI. Berichte, Briefe | L636: ='GOÄ-nÄD'!A7 -> 75 | M636: ='GOÄ-nÄD'!B7 -> Befundbericht | N636: ='GOÄ-nÄD'!C7 -> 0 | P636: ='GOÄ-nÄD'!I7 -> 0
B637: nÄD | I637: GOÄ (GOB) nÄD | J637: ='GOÄ-nÄD'!E8 -> Verband - ausgenommen Schnell- und Sprühverbände, Augen-, Ohrenklappen oder Dreiecktücher - | K637: ='GOÄ-nÄD'!G8 -> I. Anlegen von Verbänden | L637: ='GOÄ-nÄD'!A8 -> 200 | M637: ='GOÄ-nÄD'!B8 -> Verband | N637: ='GOÄ-nÄD'!C8 -> 3 | P637: ='GOÄ-nÄD'!I8 -> Wundverbände nach Nummer 200, die im Zusammenhang mit einer operativen Leistung (auch Ätzung, Fremdkörperentfernung), Punktion, Infusion, Transfusion oder Injektion durchgeführt werden, sind Bestandteil dieser Leistung.
B638: nÄD | I638: GOÄ (GOB) nÄD | J638: ='GOÄ-nÄD'!E9 -> Redressierender Klebeverband des Brustkorbs oder dachziegelförmiger Klebeverband - ausgenommen Nabelverband - | K638: ='GOÄ-nÄD'!G9 -> I. Anlegen von Verbänden | L638: ='GOÄ-nÄD'!A9 -> 201 | M638: ='GOÄ-nÄD'!B9 -> Redressierender Klebeverband Brustkorb | N638: ='GOÄ-nÄD'!C9 -> 6 | P638: ='GOÄ-nÄD'!I9 -> Wundverbände nach Nummer 200, die im Zusammenhang mit einer operativen Leistung (auch Ätzung, Fremdkörperentfernung), Punktion, Infusion, Transfusion oder Injektion durchgeführt werden, sind Bestandteil dieser Leistung.
B639: nÄD | I639: GOÄ (GOB) nÄD | J639: ='GOÄ-nÄD'!E10 -> Zirkulärer Verband des Kopfes oder des Rumpfes (auch als Wundverband); stabilisierender Verband des Halses, des Schulter- oder Hüftgelenks oder einer Extremität über mindestens zwei große Gelenke; Schanz'scher Halskrawattenverband; Kompressionsverband | K639: ='GOÄ-nÄD'!G10 -> I. Anlegen von Verbänden | L639: ='GOÄ-nÄD'!A10 -> 204 | M639: ='GOÄ-nÄD'!B10 -> Zirkulärer Verband, Rucksack oder Desault-Verband | N639: ='GOÄ-nÄD'!C10 -> 9 | P639: ='GOÄ-nÄD'!I10 -> Wundverbände nach Nummer 200, die im Zusammenhang mit einer operativen Leistung (auch Ätzung, Fremdkörperentfernung), Punktion, Infusion, Transfusion oder Injektion durchgeführt werden, sind Bestandteil dieser Leistung.
B640: nÄD | I640: GOÄ (GOB) nÄD | J640: ='GOÄ-nÄD'!E11 -> Tape-Verband eines kleinen Gelenks | K640: ='GOÄ-nÄD'!G11 -> I. Anlegen von Verbänden | L640: ='GOÄ-nÄD'!A11 -> 206 | M640: ='GOÄ-nÄD'!B11 -> Tapeverband eines kleinen Gelenks | N640: ='GOÄ-nÄD'!C11 -> 6 | P640: ='GOÄ-nÄD'!I11 -> Wundverbände nach Nummer 200, die im Zusammenhang mit einer operativen Leistung (auch Ätzung, Fremdkörperentfernung), Punktion, Infusion, Transfusion oder Injektion durchgeführt werden, sind Bestandteil dieser Leistung.
B641: nÄD | I641: GOÄ (GOB) nÄD | J641: ='GOÄ-nÄD'!E12 -> Tape-Verband eines kleinen Gelenks | K641: ='GOÄ-nÄD'!G12 -> I. Anlegen von Verbänden | L641: ='GOÄ-nÄD'!A12 -> 206 | M641: ='GOÄ-nÄD'!B12 -> Tapeverband eines kleinen Gelenks | N641: ='GOÄ-nÄD'!C12 -> 5 | P641: ='GOÄ-nÄD'!I12 -> Wundverbände nach Nummer 200, die im Zusammenhang mit einer operativen Leistung (auch Ätzung, Fremdkörperentfernung), Punktion, Infusion, Transfusion oder Injektion durchgeführt werden, sind Bestandteil dieser Leistung.
B642: nÄD | I642: GOÄ (GOB) nÄD | J642: ='GOÄ-nÄD'!E13 -> Tape-Verband eines großen Gelenks oder Zinkleimverband | K642: ='GOÄ-nÄD'!G13 -> I. Anlegen von Verbänden | L642: ='GOÄ-nÄD'!A13 -> 207 | M642: ='GOÄ-nÄD'!B13 -> Tapeverband eines großen Gelenks | N642: ='GOÄ-nÄD'!C13 -> 9 | P642: ='GOÄ-nÄD'!I13 -> Wundverbände nach Nummer 200, die im Zusammenhang mit einer operativen Leistung (auch Ätzung, Fremdkörperentfernung), Punktion, Infusion, Transfusion oder Injektion durchgeführt werden, sind Bestandteil dieser Leistung.
... B1100: nÄD | I1100: GOÄ (GOB) nÄD | J1100: ='GOÄ-nÄD'!E471 -> #N/A | K1100: ='GOÄ-nÄD'!G471 -> #N/A | L1100: ='GOÄ-nÄD'!A471 -> A618 | M1100: ='GOÄ-nÄD'!B471 -> Lungenfunktionsuntersuchung mit Medikament | N1100: ='GOÄ-nÄD'!C471 -> 40 | P1100: ='GOÄ-nÄD'!I471 -> #N/A
B1101: ÄD | I1101: EBM 2026 | L1101: ='EBM 2026'!A2 -> 1100 | M1101: ='EBM 2026'!B2 -> Unvorhergesehene Inanspruchnahme I | N1101: ='EBM 2026'!C2 -> KA | O1101: ='EBM 2026'!D2 -> ./. | P1101: ='EBM 2026'!E2 -> Keine Eignung
B1102: ÄD | I1102: EBM 2026 | L1102: ='EBM 2026'!A3 -> 1101 | M1102: ='EBM 2026'!B3 -> Unvorhergesehene Inanspruchnahme II | N1102: ='EBM 2026'!C3 -> KA | O1102: ='EBM 2026'!D3 -> ./. | P1102: ='EBM 2026'!E3 -> Keine Eignung
B1103: ÄD | I1103: EBM 2026 | L1103: ='EBM 2026'!A4 -> 1102 | M1103: ='EBM 2026'!B4 -> Inanspruchnahme an Samstagen | N1103: ='EBM 2026'!C4 -> KA | O1103: ='EBM 2026'!D4 -> ./. | P1103: ='EBM 2026'!E4 -> Keine Eignung
B1104: ÄD | I1104: EBM 2026 | L1104: ='EBM 2026'!A5 -> 1205 | M1104: ='EBM 2026'!B5 -> Notfallpauschale (Abklärung, Koordination I) | N1104: ='EBM 2026'!C5 -> 2 | O1104: ='EBM 2026'!D5 -> ./. | P1104: ='EBM 2026'!E5 -> Keine Eignung
B1105: ÄD | I1105: EBM 2026 | L1105: ='EBM 2026'!A6 -> 1207 | M1105: ='EBM 2026'!B6 -> Notfallpauschale (Abklärung, Koordination II) | N1105: ='EBM 2026'!C6 -> 2 | O1105: ='EBM 2026'!D6 -> ./. | P1105: ='EBM 2026'!E6 -> Keine Eignung
B1106: ÄD | I1106: EBM 2026 | L1106: ='EBM 2026'!A7 -> 1210 | M1106: ='EBM 2026'!B7 -> Notfallpauschale I | N1106: ='EBM 2026'!C7 -> KA | O1106: ='EBM 2026'!D7 -> ./. | P1106: ='EBM 2026'!E7 -> Keine Eignung
B1107: ÄD | I1107: EBM 2026 | L1107: ='EBM 2026'!A8 -> 1212 | M1107: ='EBM 2026'!B8 -> Notfallpauschale II | N1107: ='EBM 2026'!C8 -> KA | O1107: ='EBM 2026'!D8 -> ./. | P1107: ='EBM 2026'!E8 -> Keine Eignung
B1108: ÄD | I1108: EBM 2026 | L1108: ='EBM 2026'!A9 -> 1214 | M1108: ='EBM 2026'!B9 -> Notfallkonsultationspauschale I | N1108: ='EBM 2026'!C9 -> KA | O1108: ='EBM 2026'!D9 -> ./. | P1108: ='EBM 2026'!E9 -> Keine Eignung
B1109: ÄD | I1109: EBM 2026 | L1109: ='EBM 2026'!A10 -> 1216 | M1109: ='EBM 2026'!B10 -> Notfallkonsultationspauschale II | N1109: ='EBM 2026'!C10 -> KA | O1109: ='EBM 2026'!D10 -> ./. | P1109: ='EBM 2026'!E10 -> Keine Eignung
B1110: ÄD | I1110: EBM 2026 | L1110: ='EBM 2026'!A11 -> 1218 | M1110: ='EBM 2026'!B11 -> Notfallkonsultationspauschale III | N1110: ='EBM 2026'!C11 -> KA | O1110: ='EBM 2026'!D11 -> ./. | P1110: ='EBM 2026'!E11 -> Keine Eignung
B1111: ÄD | I1111: EBM 2026 | L1111: ='EBM 2026'!A12 -> 1220 | M1111: ='EBM 2026'!B12 -> Reanimationskomplex | N1111: ='EBM 2026'!C12 -> KA | O1111: ='EBM 2026'!D12 -> ./. | P1111: ='EBM 2026'!E12 -> Keine Eignung
...

Sheet GOÄ-ÄD
A1: GOÄ Nummer | B1: Bezeichnung | C1: in Minuten | D1: Bezugsgröße | E1: Leistung | F1: Abschnitt | G1: Unterabschnitt (Kategorie) | H1: ID | I1: Allgemeine Bestimmungen
A2: 2 | B2: Ausstellung von Wiederholungsrezepten und/oder Überweisungen | C2: 2 | D2: / Leistung | E2: =INDEX(tbl_GOAE_Leistungsverzeichnis[Leistung],MATCH(Tabelle1[[#This Row],[GOÄ Nummer]],tbl_GOAE_Leistungsverzeichnis[Mapping ID],0)) -> Ausstellung von Wiederholungsrezepten und/oder Überweisungen und/ oder Übermittlung von Befunden oder ärztlichen Anordnungen - auch mittels Fernsprecher - durch die Arzthelferin und/oder Messung von Körperzuständen (z.B. Blutdruck, Temperatur) ohne Beratung, bei einer Inanspruchnahme des Arztes | F2: =INDEX(tbl_GOAE_Leistungsverzeichnis[Abschnitt],MATCH(Tabelle1[[#This Row],[GOÄ Nummer]],tbl_GOAE_Leistungsverzeichnis[Mapping ID],0)) -> B. Grundleistungen und allgemeine Leistungen | G2: =INDEX(tbl_GOAE_Leistungsverzeichnis[Unterabschnitt (Kategorie)],MATCH(Tabelle1[[#This Row],[GOÄ Nummer]],tbl_GOAE_Leistungsverzeichnis[Mapping ID],0)) -> I. Allgemeine Beratungen und Untersuchungen | H2: =INDEX(tbl_GOAE_Leistungsverzeichnis[Nummer],MATCH(Tabelle1[[#This Row],[GOÄ Nummer]],tbl_GOAE_Leistungsverzeichnis[Mapping ID],0)) -> 2 | I2: =INDEX(tbl_GOAE_Leistungsverzeichnis[Allgemeine Bestimmungen],MATCH(Tabelle1[[#This Row],[GOÄ Nummer]],tbl_GOAE_Leistungsverzeichnis[Mapping ID],0)) -> 0
A3: 3 | B3: Eingehende, das gewöhnliche Maß übersteigende Beratung | C3: 12 | D3: / Leistung | E3: =INDEX(tbl_GOAE_Leistungsverzeichnis[Leistung],MATCH(Tabelle1[[#This Row],[GOÄ Nummer]],tbl_GOAE_Leistungsverzeichnis[Mapping ID],0)) -> Eingehende, das gewöhnliche Maß übersteigende Beratung - auch mittels Fernsprecher - | F3: =INDEX(tbl_GOAE_Leistungsverzeichnis[Abschnitt],MATCH(Tabelle1[[#This Row],[GOÄ Nummer]],tbl_GOAE_Leistungsverzeichnis[Mapping ID],0)) -> B. Grundleistungen und allgemeine Leistungen | G3: =INDEX(tbl_GOAE_Leistungsverzeichnis[Unterabschnitt (Kategorie)],MATCH(Tabelle1[[#This Row],[GOÄ Nummer]],tbl_GOAE_Leistungsverzeichnis[Mapping ID],0)) -> I. Allgemeine Beratungen und Untersuchungen | H3: =INDEX(tbl_GOAE_Leistungsverzeichnis[Nummer],MATCH(Tabelle1[[#This Row],[GOÄ Nummer]],tbl_GOAE_Leistungsverzeichnis[Mapping ID],0)) -> 3 | I3: =INDEX(tbl_GOAE_Leistungsverzeichnis[Allgemeine Bestimmungen],MATCH(Tabelle1[[#This Row],[GOÄ Nummer]],tbl_GOAE_Leistungsverzeichnis[Mapping ID],0)) -> 0
A4: 4 | B4: Erhebung der Fremdanamnese über einen Kranken | C4: 14 | D4: / Leistung | E4: =INDEX(tbl_GOAE_Leistungsverzeichnis[Leistung],MATCH(Tabelle1[[#This Row],[GOÄ Nummer]],tbl_GOAE_Leistungsverzeichnis[Mapping ID],0)) -> Erhebung der Fremdanamnese über einen Kranken und/oder Unterweisung und Führung der Bezugsperson(en) - im Zusammenhang mit der Behandlung eines Kranken - | F4: =INDEX(tbl_GOAE_Leistungsverzeichnis[Abschnitt],MATCH(Tabelle1[[#This Row],[GOÄ Nummer]],tbl_GOAE_Leistungsverzeichnis[Mapping ID],0)) -> B. Grundleistungen und allgemeine Leistungen | G4: =INDEX(tbl_GOAE_Leistungsverzeichnis[Unterabschnitt (Kategorie)],MATCH(Tabelle1[[#This Row],[GOÄ Nummer]],tbl_GOAE_Leistungsverzeichnis[Mapping ID],0)) -> I. Allgemeine Beratungen und Untersuchungen | H4: =INDEX(tbl_GOAE_Leistungsverzeichnis[Nummer],MATCH(Tabelle1[[#This Row],[GOÄ Nummer]],tbl_GOAE_Leistungsverzeichnis[Mapping ID],0)) -> 4 | I4: =INDEX(tbl_GOAE_Leistungsverzeichnis[Allgemeine Bestimmungen],MATCH(Tabelle1[[#This Row],[GOÄ Nummer]],tbl_GOAE_Leistungsverzeichnis[Mapping ID],0)) -> 0
A5: 5 | B5: Ambulante Untersuchung | C5: 15 | D5: / Leistung | E5: =INDEX(tbl_GOAE_Leistungsverzeichnis[Leistung],MATCH(Tabelle1[[#This Row],[GOÄ Nummer]],tbl_GOAE_Leistungsverzeichnis[Mapping ID],0)) -> Symptombezogene Untersuchung | F5: =INDEX(tbl_GOAE_Leistungsverzeichnis[Abschnitt],MATCH(Tabelle1[[#This Row],[GOÄ Nummer]],tbl_GOAE_Leistungsverzeichnis[Mapping ID],0)) -> B. Grundleistungen und allgemeine Leistungen | G5: =INDEX(tbl_GOAE_Leistungsverzeichnis[Unterabschnitt (Kategorie)],MATCH(Tabelle1[[#This Row],[GOÄ Nummer]],tbl_GOAE_Leistungsverzeichnis[Mapping ID],0)) -> I. Allgemeine Beratungen und Untersuchungen | H5: =INDEX(tbl_GOAE_Leistungsverzeichnis[Nummer],MATCH(Tabelle1[[#This Row],[GOÄ Nummer]],tbl_GOAE_Leistungsverzeichnis[Mapping ID],0)) -> 5 | I5: =INDEX(tbl_GOAE_Leistungsverzeichnis[Allgemeine Bestimmungen],MATCH(Tabelle1[[#This Row],[GOÄ Nummer]],tbl_GOAE_Leistungsverzeichnis[Mapping ID],0)) -> 0
A6: 8 | B6: Körperliche Untersuchung | C6: 20 | D6: / Leistung | E6: =INDEX(tbl_GOAE_Leistungsverzeichnis[Leistung],MATCH(Tabelle1[[#This Row],[GOÄ Nummer]],tbl_GOAE_Leistungsverzeichnis[Mapping ID],0)) -> Untersuchung zur Erhebung des Ganzkörperstatus, gegebenenfalls einschließlich Dokumentation | F6: =INDEX(tbl_GOAE_Leistungsverzeichnis[Abschnitt],MATCH(Tabelle1[[#This Row],[GOÄ Nummer]],tbl_GOAE_Leistungsverzeichnis[Mapping ID],0)) -> B. Grundleistungen und allgemeine Leistungen | G6: =INDEX(tbl_GOAE_Leistungsverzeichnis[Unterabschnitt (Kategorie)],MATCH(Tabelle1[[#This Row],[GOÄ Nummer]],tbl_GOAE_Leistungsverzeichnis[Mapping ID],0)) -> I. Allgemeine Beratungen und Untersuchungen | H6: =INDEX(tbl_GOAE_Leistungsverzeichnis[Nummer],MATCH(Tabelle1[[#This Row],[GOÄ Nummer]],tbl_GOAE_Leistungsverzeichnis[Mapping ID],0)) -> 8 | I6: =INDEX(tbl_GOAE_Leistungsverzeichnis[Allgemeine Bestimmungen],MATCH(Tabelle1[[#This Row],[GOÄ Nummer]],tbl_GOAE_Leistungsverzeichnis[Mapping ID],0)) -> 0
A7: 11 | B7: Digitaluntersuchung Darm | C7: 4 | D7: / Leistung | E7: =INDEX(tbl_GOAE_Leistungsverzeichnis[Leistung],MATCH(Tabelle1[[#This Row],[GOÄ Nummer]],tbl_GOAE_Leistungsverzeichnis[Mapping ID],0)) -> Digitaluntersuchung des Mastdarms und/oder der Prostata | F7: =INDEX(tbl_GOAE_Leistungsverzeichnis[Abschnitt],MATCH(Tabelle1[[#This Row],[GOÄ Nummer]],tbl_GOAE_Leistungsverzeichnis[Mapping ID],0)) -> B. Grundleistungen und allgemeine Leistungen | G7: =INDEX(tbl_GOAE_Leistungsverzeichnis[Unterabschnitt (Kategorie)],MATCH(Tabelle1[[#This Row],[GOÄ Nummer]],tbl_GOAE_Leistungsverzeichnis[Mapping ID],0)) -> I. Allgemeine Beratungen und Untersuchungen | H7: =INDEX(tbl_GOAE_Leistungsverzeichnis[Nummer],MATCH(Tabelle1[[#This Row],[GOÄ Nummer]],tbl_GOAE_Leistungsverzeichnis[Mapping ID],0)) -> 11 | I7: =INDEX(tbl_GOAE_Leistungsverzeichnis[Allgemeine Bestimmungen],MATCH(Tabelle1[[#This Row],[GOÄ Nummer]],tbl_GOAE_Leistungsverzeichnis[Mapping ID],0)) -> 0
A8: 15 | B8: Einleitung und Koordination flankierender therapeutischer und sozialer Maßnahmen | C8: 15 | D8: / Leistung | E8: =INDEX(tbl_GOAE_Leistungsverzeichnis[Leistung],MATCH(Tabelle1[[#This Row],[GOÄ Nummer]],tbl_GOAE_Leistungsverzeichnis[Mapping ID],0)) -> Einleitung und Koordination flankierender therapeutischer und sozialer Maßnahmen während der kontinuierlichen ambulanten Betreuung eines chronisch Kranken | F8: =INDEX(tbl_GOAE_Leistungsverzeichnis[Abschnitt],MATCH(Tabelle1[[#This Row],[GOÄ Nummer]],tbl_GOAE_Leistungsverzeichnis[Mapping ID],0)) -> B. Grundleistungen und allgemeine Leistungen | G8: =INDEX(tbl_GOAE_Leistungsverzeichnis[Unterabschnitt (Kategorie)],MATCH(Tabelle1[[#This Row],[GOÄ Nummer]],tbl_GOAE_Leistungsverzeichnis[Mapping ID],0)) -> I. Allgemeine Beratungen und Untersuchungen | H8: =INDEX(tbl_GOAE_Leistungsverzeichnis[Nummer],MATCH(Tabelle1[[#This Row],[GOÄ Nummer]],tbl_GOAE_Leistungsverzeichnis[Mapping ID],0)) -> 15 | I8: =INDEX(tbl_GOAE_Leistungsverzeichnis[Allgemeine Bestimmungen],MATCH(Tabelle1[[#This Row],[GOÄ Nummer]],tbl_GOAE_Leistungsverzeichnis[Mapping ID],0)) -> 0
A9: 27 | B9: Untersuchung einer Frau zur Früherkennung von Krebserkrankungen | C9: 26 | D9: / Leistung | E9: =INDEX(tbl_GOAE_Leistungsverzeichnis[Leistung],MATCH(Tabelle1[[#This Row],[GOÄ Nummer]],tbl_GOAE_Leistungsverzeichnis[Mapping ID],0)) -> Untersuchung einer Frau zur Früherkennung von Krebserkrankungen der Brust, des Genitales, des Rektums und der Haut - einschließlich Erhebung der Anamnese, Abstrichentnahme zur zytologischen Untersuchung, Untersuchung auf Blut im Stuhl und Urinuntersuchung auf Eiweiß, Zucker und Erythrozyten, einschließlich Beratung - | F9: =INDEX(tbl_GOAE_Leistungsverzeichnis[Abschnitt],MATCH(Tabelle1[[#This Row],[GOÄ Nummer]],tbl_GOAE_Leistungsverzeichnis[Mapping ID],0)) -> B. Grundleistungen und allgemeine Leistungen | G9: =INDEX(tbl_GOAE_Leistungsverzeichnis[Unterabschnitt (Kategorie)],MATCH(Tabelle1[[#This Row],[GOÄ Nummer]],tbl_GOAE_Leistungsverzeichnis[Mapping ID],0)) -> II. Zuschläge zu Beratungen und Untersuchungen nach Nummer 1, 3, 4, 5, 6, 7 oder 8 | H9: =INDEX(tbl_GOAE_Leistungsverzeichnis[Nummer],MATCH(Tabelle1[[#This Row],[GOÄ Nummer]],tbl_GOAE_Leistungsverzeichnis[Mapping ID],0)) -> 27 | I9: =INDEX(tbl_GOAE_Leistungsverzeichnis[Allgemeine Bestimmungen],MATCH(Tabelle1[[#This Row],[GOÄ Nummer]],tbl_GOAE_Leistungsverzeichnis[Mapping ID],0)) -> Die Zuschläge nach den Buchstaben A bis D sowie K 1 sind nur mit dem einfachen Gebührensatz berechnungsfähig. Sie dürfen unabhängig von der Anzahl und Kombination der erbrachten Leistungen je Inanspruchnahme des Arztes nur einmal berechnet werden. Neben den Zuschlägen nach den Buchstaben A bis
A10: 28 | B10: Untersuchung eines Mannes zur Früherkennung von Krebserkrankungen | C10: 18 | D10: / Leistung | E10: =INDEX(tbl_GOAE_Leistungsverzeichnis[Leistung],MATCH(Tabelle1[[#This Row],[GOÄ Nummer]],tbl_GOAE_Leistungsverzeichnis[Mapping ID],0)) -> Untersuchung eines Mannes zur Früherkennung von Krebserkrankungen des Rektums, der Prostata, des äußeren Genitales und der Haut - einschließlich Erhebung der Anamnese, Urinuntersuchung auf Eiweiß, Zucker und Erythrozyten sowie Untersuchung auf Blut im Stuhl, einschließlich Beratung - | F10: =INDEX(tbl_GOAE_Leistungsverzeichnis[Abschnitt],MATCH(Tabelle1[[#This Row],[GOÄ Nummer]],tbl_GOAE_Leistungsverzeichnis[Mapping ID],0)) -> B. Grundleistungen und allgemeine Leistungen | G10: =INDEX(tbl_GOAE_Leistungsverzeichnis[Unterabschnitt (Kategorie)],MATCH(Tabelle1[[#This Row],[GOÄ Nummer]],tbl_GOAE_Leistungsverzeichnis[Mapping ID],0)) -> II. Zuschläge zu Beratungen und Untersuchungen nach Nummer 1, 3, 4, 5, 6, 7 oder 8 | H10: =INDEX(tbl_GOAE_Leistungsverzeichnis[Nummer],MATCH(Tabelle1[[#This Row],[GOÄ Nummer]],tbl_GOAE_Leistungsverzeichnis[Mapping ID],0)) -> 28 | I10: =INDEX(tbl_GOAE_Leistungsverzeichnis[Allgemeine Bestimmungen],MATCH(Tabelle1[[#This Row],[GOÄ Nummer]],tbl_GOAE_Leistungsverzeichnis[Mapping ID],0)) -> Die Zuschläge nach den Buchstaben A bis D sowie K 1 sind nur mit dem einfachen Gebührensatz berechnungsfähig. Sie dürfen unabhängig von der Anzahl und Kombination der erbrachten Leistungen je Inanspruchnahme des Arztes nur einmal berechnet werden. Neben den Zuschlägen nach den Buchstaben A bis
A11: 34 | B11: Erörterung (Dauer min. 20 Minuten) der Auswirkung einer Krankheit | C11: 20 | D11: / Leistung | E11: =INDEX(tbl_GOAE_Leistungsverzeichnis[Leistung],MATCH(Tabelle1[[#This Row],[GOÄ Nummer]],tbl_GOAE_Leistungsverzeichnis[Mapping ID],0)) -> Erörterung (Dauer mindestens 20 Minuten) der Auswirkungen einer Krankheit auf die Lebensgestaltung in unmittelbarem Zusammenhang mit der Feststellung oder erheblichen Verschlimmerung einer nachhaltig lebensverändernden oder lebensbedrohenden Erkrankung - gegebenenfalls einschließlich Planung eines operativen Eingriffs und Abwägung seiner Konsequenzen und Risiken -, einschließlich Beratung - gegebenenfalls unter Einbeziehung von Bezugspersonen - | F11: =INDEX(tbl_GOAE_Leistungsverzeichnis[Abschnitt],MATCH(Tabelle1[[#This Row],[GOÄ Nummer]],tbl_GOAE_Leistungsverzeichnis[Mapping ID],0)) -> B. Grundleistungen und allgemeine Leistungen | G11: =INDEX(tbl_GOAE_Leistungsverzeichnis[Unterabschnitt (Kategorie)],MATCH(Tabelle1[[#This Row],[GOÄ Nummer]],tbl_GOAE_Leistungsverzeichnis[Mapping ID],0)) -> II. Zuschläge zu Beratungen und Untersuchungen nach Nummer 1, 3, 4, 5, 6, 7 oder 8 | H11: =INDEX(tbl_GOAE_Leistungsverzeichnis[Nummer],MATCH(Tabelle1[[#This Row],[GOÄ Nummer]],tbl_GOAE_Leistungsverzeichnis[Mapping ID],0)) -> 34 | I11: =INDEX(tbl_GOAE_Leistungsverzeichnis[Allgemeine Bestimmungen],MATCH(Tabelle1[[#This Row],[GOÄ Nummer]],tbl_GOAE_Leistungsverzeichnis[Mapping ID],0)) -> Die Zuschläge nach den Buchstaben A bis D sowie K 1 sind nur mit dem einfachen Gebührensatz berechnungsfähig. Sie dürfen unabhängig von der Anzahl und Kombination der erbrachten Leistungen je Inanspruchnahme des Arztes nur einmal berechnet werden. Neben den Zuschlägen nach den Buchstaben A bis
A12: 60 | B12: Konsiliarische Erörterung zwischen zwei oder mehr Ärzten | C12: 10 | D12: / Leistung | E12: =INDEX(tbl_GOAE_Leistungsverzeichnis[Leistung],MATCH(Tabelle1[[#This Row],[GOÄ Nummer]],tbl_GOAE_Leistungsverzeichnis[Mapping ID],0)) -> Konsiliarische Erörterung zwischen zwei oder mehr liquidationsberechtigten Ärzten, für jeden Arzt | F12: =INDEX(tbl_GOAE_Leistungsverzeichnis[Abschnitt],MATCH(Tabelle1[[#This Row],[GOÄ Nummer]],tbl_GOAE_Leistungsverzeichnis[Mapping ID],0)) -> B. Grundleistungen und allgemeine Leistungen | G12: =INDEX(tbl_GOAE_Leistungsverzeichnis[Unterabschnitt (Kategorie)],MATCH(Tabelle1[[#This Row],[GOÄ Nummer]],tbl_GOAE_Leistungsverzeichnis[Mapping ID],0)) -> IV. Visiten, Konsiliartätigkeit, Besuche, Assistenz | H12: =INDEX(tbl_GOAE_Leistungsverzeichnis[Nummer],MATCH(Tabelle1[[#This Row],[GOÄ Nummer]],tbl_GOAE_Leistungsverzeichnis[Mapping ID],0)) -> 60 | I12: =INDEX(tbl_GOAE_Leistungsverzeichnis[Allgemeine Bestimmungen],MATCH(Tabelle1[[#This Row],[GOÄ Nummer]],tbl_GOAE_Leistungsverzeichnis[Mapping ID],0)) -> 0
A13: 70 | B13: Kurze Bescheinigung | C13: 1 | D13: / Leistung | E13: =INDEX(tbl_GOAE_Leistungsverzeichnis[Leistung],MATCH(Tabelle1[[#This Row],[GOÄ Nummer]],tbl_GOAE_Leistungsverzeichnis[Mapping ID],0)) -> Kurze Bescheinigung oder kurzes Zeugnis, Arbeitsunfähigkeitsbescheinigung | F13: =INDEX(tbl_GOAE_Leistungsverzeichnis[Abschnitt],MATCH(Tabelle1[[#This Row],[GOÄ Nummer]],tbl_GOAE_Leistungsverzeichnis[Mapping ID],0)) -> B. Grundleistungen und allgemeine Leistungen | G13: =INDEX(tbl_GOAE_Leistungsverzeichnis[Unterabschnitt (Kategorie)],MATCH(Tabelle1[[#This Row],[GOÄ Nummer]],tbl_GOAE_Leistungsverzeichnis[Mapping ID],0)) -> VI. Berichte, Briefe | H13: =INDEX(tbl_GOAE_Leistungsverzeichnis[Nummer],MATCH(Tabelle1[[#This Row],[GOÄ Nummer]],tbl_GOAE_Leistungsverzeichnis[Mapping ID],0)) -> 70 | I13: =INDEX(tbl_GOAE_Leistungsverzeichnis[Allgemeine Bestimmungen],MATCH(Tabelle1[[#This Row],[GOÄ Nummer]],tbl_GOAE_Leistungsverzeichnis[Mapping ID],0)) -> 0
... A622: 6100 | B622: Kernspintomographie | C622: 60 | D622: / Leistung | E622: =INDEX(tbl_GOAE_Leistungsverzeichnis[Leistung],MATCH(Tabelle1[[#This Row],[GOÄ Nummer]],tbl_GOAE_Leistungsverzeichnis[Mapping ID],0)) -> #N/A | F622: =INDEX(tbl_GOAE_Leistungsverzeichnis[Abschnitt],MATCH(Tabelle1[[#This Row],[GOÄ Nummer]],tbl_GOAE_Leistungsverzeichnis[Mapping ID],0)) -> #N/A | G622: =INDEX(tbl_GOAE_Leistungsverzeichnis[Unterabschnitt (Kategorie)],MATCH(Tabelle1[[#This Row],[GOÄ Nummer]],tbl_GOAE_Leistungsverzeichnis[Mapping ID],0)) -> #N/A | H622: =INDEX(tbl_GOAE_Leistungsverzeichnis[Nummer],MATCH(Tabelle1[[#This Row],[GOÄ Nummer]],tbl_GOAE_Leistungsverzeichnis[Mapping ID],0)) -> #N/A | I622: =INDEX(tbl_GOAE_Leistungsverzeichnis[Allgemeine Bestimmungen],MATCH(Tabelle1[[#This Row],[GOÄ Nummer]],tbl_GOAE_Leistungsverzeichnis[Mapping ID],0)) -> #N/A
A623: 286a | B623: Rehinfusion jeder weiteren Einheit (mindestens 200ml) Eigenblut oder Eigenplasma im Anschluss an die Leistung nach der Nummer 286 einschl. Identitätssicherung im AB0 System (Bedsidetest) | C623: 8 | D623: / Leistung | E623: =INDEX(tbl_GOAE_Leistungsverzeichnis[Leistung],MATCH(Tabelle1[[#This Row],[GOÄ Nummer]],tbl_GOAE_Leistungsverzeichnis[Mapping ID],0)) -> #N/A | F623: =INDEX(tbl_GOAE_Leistungsverzeichnis[Abschnitt],MATCH(Tabelle1[[#This Row],[GOÄ Nummer]],tbl_GOAE_Leistungsverzeichnis[Mapping ID],0)) -> #N/A | G623: =INDEX(tbl_GOAE_Leistungsverzeichnis[Unterabschnitt (Kategorie)],MATCH(Tabelle1[[#This Row],[GOÄ Nummer]],tbl_GOAE_Leistungsverzeichnis[Mapping ID],0)) -> #N/A | H623: =INDEX(tbl_GOAE_Leistungsverzeichnis[Nummer],MATCH(Tabelle1[[#This Row],[GOÄ Nummer]],tbl_GOAE_Leistungsverzeichnis[Mapping ID],0)) -> #N/A | I623: =INDEX(tbl_GOAE_Leistungsverzeichnis[Allgemeine Bestimmungen],MATCH(Tabelle1[[#This Row],[GOÄ Nummer]],tbl_GOAE_Leistungsverzeichnis[Mapping ID],0)) -> #N/A
A624: 605a | B624: Darstellung der Flussvolumenkurve bei spirographischen Untersuchungen | C624: 6 | D624: / Leistung | E624: =INDEX(tbl_GOAE_Leistungsverzeichnis[Leistung],MATCH(Tabelle1[[#This Row],[GOÄ Nummer]],tbl_GOAE_Leistungsverzeichnis[Mapping ID],0)) -> #N/A | F624: =INDEX(tbl_GOAE_Leistungsverzeichnis[Abschnitt],MATCH(Tabelle1[[#This Row],[GOÄ Nummer]],tbl_GOAE_Leistungsverzeichnis[Mapping ID],0)) -> #N/A | G624: =INDEX(tbl_GOAE_Leistungsverzeichnis[Unterabschnitt (Kategorie)],MATCH(Tabelle1[[#This Row],[GOÄ Nummer]],tbl_GOAE_Leistungsverzeichnis[Mapping ID],0)) -> #N/A | H624: =INDEX(tbl_GOAE_Leistungsverzeichnis[Nummer],MATCH(Tabelle1[[#This Row],[GOÄ Nummer]],tbl_GOAE_Leistungsverzeichnis[Mapping ID],0)) -> #N/A | I624: =INDEX(tbl_GOAE_Leistungsverzeichnis[Allgemeine Bestimmungen],MATCH(Tabelle1[[#This Row],[GOÄ Nummer]],tbl_GOAE_Leistungsverzeichnis[Mapping ID],0)) -> #N/A
A625: 827a | B625: Schlafentzugs-EEG | C625: 20 | D625: / Leistung | E625: =INDEX(tbl_GOAE_Leistungsverzeichnis[Leistung],MATCH(Tabelle1[[#This Row],[GOÄ Nummer]],tbl_GOAE_Leistungsverzeichnis[Mapping ID],0)) -> #N/A | F625: =INDEX(tbl_GOAE_Leistungsverzeichnis[Abschnitt],MATCH(Tabelle1[[#This Row],[GOÄ Nummer]],tbl_GOAE_Leistungsverzeichnis[Mapping ID],0)) -> #N/A | G625: =INDEX(tbl_GOAE_Leistungsverzeichnis[Unterabschnitt (Kategorie)],MATCH(Tabelle1[[#This Row],[GOÄ Nummer]],tbl_GOAE_Leistungsverzeichnis[Mapping ID],0)) -> #N/A | H625: =INDEX(tbl_GOAE_Leistungsverzeichnis[Nummer],MATCH(Tabelle1[[#This Row],[GOÄ Nummer]],tbl_GOAE_Leistungsverzeichnis[Mapping ID],0)) -> #N/A | I625: =INDEX(tbl_GOAE_Leistungsverzeichnis[Allgemeine Bestimmungen],MATCH(Tabelle1[[#This Row],[GOÄ Nummer]],tbl_GOAE_Leistungsverzeichnis[Mapping ID],0)) -> #N/A
A626: A353 | B626: Einbringung des Kontrastmittels mittels intraarterieller Hochdruckinjektion zur selektive Arteriographie (z.B. Nierenarterie), einschließlich Röntgenkontrolle und ggf. fortlaufender EKG Kontrolle, je | C626: 38 | D626: / Leistung | E626: =INDEX(tbl_GOAE_Leistungsverzeichnis[Leistung],MATCH(Tabelle1[[#This Row],[GOÄ Nummer]],tbl_GOAE_Leistungsverzeichnis[Mapping ID],0)) -> #N/A | F626: =INDEX(tbl_GOAE_Leistungsverzeichnis[Abschnitt],MATCH(Tabelle1[[#This Row],[GOÄ Nummer]],tbl_GOAE_Leistungsverzeichnis[Mapping ID],0)) -> #N/A | G626: =INDEX(tbl_GOAE_Leistungsverzeichnis[Unterabschnitt (Kategorie)],MATCH(Tabelle1[[#This Row],[GOÄ Nummer]],tbl_GOAE_Leistungsverzeichnis[Mapping ID],0)) -> #N/A | H626: =INDEX(tbl_GOAE_Leistungsverzeichnis[Nummer],MATCH(Tabelle1[[#This Row],[GOÄ Nummer]],tbl_GOAE_Leistungsverzeichnis[Mapping ID],0)) -> #N/A | I626: =INDEX(tbl_GOAE_Leistungsverzeichnis[Allgemeine Bestimmungen],MATCH(Tabelle1[[#This Row],[GOÄ Nummer]],tbl_GOAE_Leistungsverzeichnis[Mapping ID],0)) -> #N/A
A627: A795 | B627: Kipptisch-Untersuchung | C627: 20 | D627: / Leistung | E627: =INDEX(tbl_GOAE_Leistungsverzeichnis[Leistung],MATCH(Tabelle1[[#This Row],[GOÄ Nummer]],tbl_GOAE_Leistungsverzeichnis[Mapping ID],0)) -> #N/A | F627: =INDEX(tbl_GOAE_Leistungsverzeichnis[Abschnitt],MATCH(Tabelle1[[#This Row],[GOÄ Nummer]],tbl_GOAE_Leistungsverzeichnis[Mapping ID],0)) -> #N/A | G627: =INDEX(tbl_GOAE_Leistungsverzeichnis[Unterabschnitt (Kategorie)],MATCH(Tabelle1[[#This Row],[GOÄ Nummer]],tbl_GOAE_Leistungsverzeichnis[Mapping ID],0)) -> #N/A | H627: =INDEX(tbl_GOAE_Leistungsverzeichnis[Nummer],MATCH(Tabelle1[[#This Row],[GOÄ Nummer]],tbl_GOAE_Leistungsverzeichnis[Mapping ID],0)) -> #N/A | I627: =INDEX(tbl_GOAE_Leistungsverzeichnis[Allgemeine Bestimmungen],MATCH(Tabelle1[[#This Row],[GOÄ Nummer]],tbl_GOAE_Leistungsverzeichnis[Mapping ID],0)) -> #N/A
A628: A888 | B628: Psychiatrische Behandlung zur Reintegration eines Erwachsenen als Gruppenbehandlung | C628: 12 | D628: / Leistung | E628: =INDEX(tbl_GOAE_Leistungsverzeichnis[Leistung],MATCH(Tabelle1[[#This Row],[GOÄ Nummer]],tbl_GOAE_Leistungsverzeichnis[Mapping ID],0)) -> #N/A | F628: =INDEX(tbl_GOAE_Leistungsverzeichnis[Abschnitt],MATCH(Tabelle1[[#This Row],[GOÄ Nummer]],tbl_GOAE_Leistungsverzeichnis[Mapping ID],0)) -> #N/A | G628: =INDEX(tbl_GOAE_Leistungsverzeichnis[Unterabschnitt (Kategorie)],MATCH(Tabelle1[[#This Row],[GOÄ Nummer]],tbl_GOAE_Leistungsverzeichnis[Mapping ID],0)) -> #N/A | H628: =INDEX(tbl_GOAE_Leistungsverzeichnis[Nummer],MATCH(Tabelle1[[#This Row],[GOÄ Nummer]],tbl_GOAE_Leistungsverzeichnis[Mapping ID],0)) -> #N/A | I628: =INDEX(tbl_GOAE_Leistungsverzeichnis[Allgemeine Bestimmungen],MATCH(Tabelle1[[#This Row],[GOÄ Nummer]],tbl_GOAE_Leistungsverzeichnis[Mapping ID],0)) -> #N/A

Sheet GOÄ-nÄD
A1: GOÄ Nummer | B1: Bezeichnung | C1: in Minuten | D1: Bezugsgröße | E1: Leistung | F1: Abschnitt | G1: Unterabschnitt (Kategorie) | H1: ID | I1: Allgemeine Bestimmungen
A2: 1 | B2: Angehörigenberatung | C2: 30 | D2: Min. / Beratung | E2: =INDEX(tbl_GOAE_Leistungsverzeichnis[Leistung],MATCH(Tabelle5[[#This Row],[GOÄ Nummer]],tbl_GOAE_Leistungsverzeichnis[Mapping ID],0)) -> Beratung - auch mittels Fernsprecher - | F2: =INDEX(tbl_GOAE_Leistungsverzeichnis[Abschnitt],MATCH(Tabelle5[[#This Row],[GOÄ Nummer]],tbl_GOAE_Leistungsverzeichnis[Mapping ID],0)) -> B. Grundleistungen und allgemeine Leistungen | G2: =INDEX(tbl_GOAE_Leistungsverzeichnis[Unterabschnitt (Kategorie)],MATCH(Tabelle5[[#This Row],[GOÄ Nummer]],tbl_GOAE_Leistungsverzeichnis[Mapping ID],0)) -> I. Allgemeine Beratungen und Untersuchungen | H2: =INDEX(tbl_GOAE_Leistungsverzeichnis[Nummer],MATCH(Tabelle5[[#This Row],[GOÄ Nummer]],tbl_GOAE_Leistungsverzeichnis[Mapping ID],0)) -> 1 | I2: =INDEX(tbl_GOAE_Leistungsverzeichnis[Allgemeine Bestimmungen],MATCH(Tabelle5[[#This Row],[GOÄ Nummer]],tbl_GOAE_Leistungsverzeichnis[Mapping ID],0)) -> 0
A3: 2 | B3: Ausstellung von Wiederholungsrezepten und/oder Überweisungen | C3: 2 | D3: Min. / Patient | E3: =INDEX(tbl_GOAE_Leistungsverzeichnis[Leistung],MATCH(Tabelle5[[#This Row],[GOÄ Nummer]],tbl_GOAE_Leistungsverzeichnis[Mapping ID],0)) -> Ausstellung von Wiederholungsrezepten und/oder Überweisungen und/ oder Übermittlung von Befunden oder ärztlichen Anordnungen - auch mittels Fernsprecher - durch die Arzthelferin und/oder Messung von Körperzuständen (z.B. Blutdruck, Temperatur) ohne Beratung, bei einer Inanspruchnahme des Arztes | F3: =INDEX(tbl_GOAE_Leistungsverzeichnis[Abschnitt],MATCH(Tabelle5[[#This Row],[GOÄ Nummer]],tbl_GOAE_Leistungsverzeichnis[Mapping ID],0)) -> B. Grundleistungen und allgemeine Leistungen | G3: =INDEX(tbl_GOAE_Leistungsverzeichnis[Unterabschnitt (Kategorie)],MATCH(Tabelle5[[#This Row],[GOÄ Nummer]],tbl_GOAE_Leistungsverzeichnis[Mapping ID],0)) -> I. Allgemeine Beratungen und Untersuchungen | H3: =INDEX(tbl_GOAE_Leistungsverzeichnis[Nummer],MATCH(Tabelle5[[#This Row],[GOÄ Nummer]],tbl_GOAE_Leistungsverzeichnis[Mapping ID],0)) -> 2 | I3: =INDEX(tbl_GOAE_Leistungsverzeichnis[Allgemeine Bestimmungen],MATCH(Tabelle5[[#This Row],[GOÄ Nummer]],tbl_GOAE_Leistungsverzeichnis[Mapping ID],0)) -> 0
A4: 8 | B4: Körperliche Untersuchung | C4: 12.5 | D4: Min. / Patient | E4: =INDEX(tbl_GOAE_Leistungsverzeichnis[Leistung],MATCH(Tabelle5[[#This Row],[GOÄ Nummer]],tbl_GOAE_Leistungsverzeichnis[Mapping ID],0)) -> Untersuchung zur Erhebung des Ganzkörperstatus, gegebenenfalls einschließlich Dokumentation | F4: =INDEX(tbl_GOAE_Leistungsverzeichnis[Abschnitt],MATCH(Tabelle5[[#This Row],[GOÄ Nummer]],tbl_GOAE_Leistungsverzeichnis[Mapping ID],0)) -> B. Grundleistungen und allgemeine Leistungen | G4: =INDEX(tbl_GOAE_Leistungsverzeichnis[Unterabschnitt (Kategorie)],MATCH(Tabelle5[[#This Row],[GOÄ Nummer]],tbl_GOAE_Leistungsverzeichnis[Mapping ID],0)) -> I. Allgemeine Beratungen und Untersuchungen | H4: =INDEX(tbl_GOAE_Leistungsverzeichnis[Nummer],MATCH(Tabelle5[[#This Row],[GOÄ Nummer]],tbl_GOAE_Leistungsverzeichnis[Mapping ID],0)) -> 8 | I4: =INDEX(tbl_GOAE_Leistungsverzeichnis[Allgemeine Bestimmungen],MATCH(Tabelle5[[#This Row],[GOÄ Nummer]],tbl_GOAE_Leistungsverzeichnis[Mapping ID],0)) -> 0
A5: 11 | B5: Digitaluntersuchung Darm | C5: 5 | D5: Min. / Patient | E5: =INDEX(tbl_GOAE_Leistungsverzeichnis[Leistung],MATCH(Tabelle5[[#This Row],[GOÄ Nummer]],tbl_GOAE_Leistungsverzeichnis[Mapping ID],0)) -> Digitaluntersuchung des Mastdarms und/oder der Prostata | F5: =INDEX(tbl_GOAE_Leistungsverzeichnis[Abschnitt],MATCH(Tabelle5[[#This Row],[GOÄ Nummer]],tbl_GOAE_Leistungsverzeichnis[Mapping ID],0)) -> B. Grundleistungen und allgemeine Leistungen | G5: =INDEX(tbl_GOAE_Leistungsverzeichnis[Unterabschnitt (Kategorie)],MATCH(Tabelle5[[#This Row],[GOÄ Nummer]],tbl_GOAE_Leistungsverzeichnis[Mapping ID],0)) -> I. Allgemeine Beratungen und Untersuchungen | H5: =INDEX(tbl_GOAE_Leistungsverzeichnis[Nummer],MATCH(Tabelle5[[#This Row],[GOÄ Nummer]],tbl_GOAE_Leistungsverzeichnis[Mapping ID],0)) -> 11 | I5: =INDEX(tbl_GOAE_Leistungsverzeichnis[Allgemeine Bestimmungen],MATCH(Tabelle5[[#This Row],[GOÄ Nummer]],tbl_GOAE_Leistungsverzeichnis[Mapping ID],0)) -> 0
A6: 33 | B6: Strukturierte Schulung einer Einzelperson mit einer Mindestdauer von 20 Min. (bei Diabetes, Gestationsdiabetes oder Zustand nach Pankrea- tektomie) - einschl. Evaluation zur Qualitätssicherung | C6: 20 | D6: Min. / Patient | E6: =INDEX(tbl_GOAE_Leistungsverzeichnis[Leistung],MATCH(Tabelle5[[#This Row],[GOÄ Nummer]],tbl_GOAE_Leistungsverzeichnis[Mapping ID],0)) -> Strukturierte Schulung einer Einzelperson mit einer Mindestdauer von 20 Minuten (bei Diabetes, Gestationsdiabetes oder Zustand nach Pankreatektomie) - einschließlich Evaluation zur Qualitätssicherung unter diabetologischen Gesichtspunkten zum Erlernen und Umsetzen des Behandlungsmanagements, einschließlich der Auswertung eines standardisierten Fragebogens - | F6: =INDEX(tbl_GOAE_Leistungsverzeichnis[Abschnitt],MATCH(Tabelle5[[#This Row],[GOÄ Nummer]],tbl_GOAE_Leistungsverzeichnis[Mapping ID],0)) -> B. Grundleistungen und allgemeine Leistungen | G6: =INDEX(tbl_GOAE_Leistungsverzeichnis[Unterabschnitt (Kategorie)],MATCH(Tabelle5[[#This Row],[GOÄ Nummer]],tbl_GOAE_Leistungsverzeichnis[Mapping ID],0)) -> II. Zuschläge zu Beratungen und Untersuchungen nach Nummer 1, 3, 4, 5, 6, 7 oder 8 | H6: =INDEX(tbl_GOAE_Leistungsverzeichnis[Nummer],MATCH(Tabelle5[[#This Row],[GOÄ Nummer]],tbl_GOAE_Leistungsverzeichnis[Mapping ID],0)) -> 33 | I6: =INDEX(tbl_GOAE_Leistungsverzeichnis[Allgemeine Bestimmungen],MATCH(Tabelle5[[#This Row],[GOÄ Nummer]],tbl_GOAE_Leistungsverzeichnis[Mapping ID],0)) -> Die Zuschläge nach den Buchstaben A bis D sowie K 1 sind nur mit dem einfachen Gebührensatz berechnungsfähig. Sie dürfen unabhängig von der Anzahl und Kombination der erbrachten Leistungen je Inanspruchnahme des Arztes nur einmal berechnet werden. Neben den Zuschlägen nach den Buchstaben A bis
A7: 75 | B7: Befundbericht | C7: 0 | D7: Min. / Patient | E7: =INDEX(tbl_GOAE_Leistungsverzeichnis[Leistung],MATCH(Tabelle5[[#This Row],[GOÄ Nummer]],tbl_GOAE_Leistungsverzeichnis[Mapping ID],0)) -> Ausführlicher schriftlicher Krankheits- und Befundbericht (einschließlich Angaben zur Anamnese, zu dem(n) Befund(en), zur epikritischen Bewertung und gegebenenfalls zur Therapie) | F7: =INDEX(tbl_GOAE_Leistungsverzeichnis[Abschnitt],MATCH(Tabelle5[[#This Row],[GOÄ Nummer]],tbl_GOAE_Leistungsverzeichnis[Mapping ID],0)) -> B. Grundleistungen und allgemeine Leistungen | G7: =INDEX(tbl_GOAE_Leistungsverzeichnis[Unterabschnitt (Kategorie)],MATCH(Tabelle5[[#This Row],[GOÄ Nummer]],tbl_GOAE_Leistungsverzeichnis[Mapping ID],0)) -> VI. Berichte, Briefe | H7: =INDEX(tbl_GOAE_Leistungsverzeichnis[Nummer],MATCH(Tabelle5[[#This Row],[GOÄ Nummer]],tbl_GOAE_Leistungsverzeichnis[Mapping ID],0)) -> 75 | I7: =INDEX(tbl_GOAE_Leistungsverzeichnis[Allgemeine Bestimmungen],MATCH(Tabelle5[[#This Row],[GOÄ Nummer]],tbl_GOAE_Leistungsverzeichnis[Mapping ID],0)) -> 0
A8: 200 | B8: Verband | C8: 3 | D8: Min. / Patient | E8: =INDEX(tbl_GOAE_Leistungsverzeichnis[Leistung],MATCH(Tabelle5[[#This Row],[GOÄ Nummer]],tbl_GOAE_Leistungsverzeichnis[Mapping ID],0)) -> Verband - ausgenommen Schnell- und Sprühverbände, Augen-, Ohrenklappen oder Dreiecktücher - | F8: =INDEX(tbl_GOAE_Leistungsverzeichnis[Abschnitt],MATCH(Tabelle5[[#This Row],[GOÄ Nummer]],tbl_GOAE_Leistungsverzeichnis[Mapping ID],0)) -> C. Nichtgebietsbezogene Sonderleistungen | G8: =INDEX(tbl_GOAE_Leistungsverzeichnis[Unterabschnitt (Kategorie)],MATCH(Tabelle5[[#This Row],[GOÄ Nummer]],tbl_GOAE_Leistungsverzeichnis[Mapping ID],0)) -> I. Anlegen von Verbänden | H8: =INDEX(tbl_GOAE_Leistungsverzeichnis[Nummer],MATCH(Tabelle5[[#This Row],[GOÄ Nummer]],tbl_GOAE_Leistungsverzeichnis[Mapping ID],0)) -> 200 | I8: =INDEX(tbl_GOAE_Leistungsverzeichnis[Allgemeine Bestimmungen],MATCH(Tabelle5[[#This Row],[GOÄ Nummer]],tbl_GOAE_Leistungsverzeichnis[Mapping ID],0)) -> Wundverbände nach Nummer 200, die im Zusammenhang mit einer operativen Leistung (auch Ätzung, Fremdkörperentfernung), Punktion, Infusion, Transfusion oder Injektion durchgeführt werden, sind Bestandteil dieser Leistung.
A9: 201 | B9: Redressierender Klebeverband Brustkorb | C9: 6 | D9: Min. / Patient | E9: =INDEX(tbl_GOAE_Leistungsverzeichnis[Leistung],MATCH(Tabelle5[[#This Row],[GOÄ Nummer]],tbl_GOAE_Leistungsverzeichnis[Mapping ID],0)) -> Redressierender Klebeverband des Brustkorbs oder dachziegelförmiger Klebeverband - ausgenommen Nabelverband - | F9: =INDEX(tbl_GOAE_Leistungsverzeichnis[Abschnitt],MATCH(Tabelle5[[#This Row],[GOÄ Nummer]],tbl_GOAE_Leistungsverzeichnis[Mapping ID],0)) -> C. Nichtgebietsbezogene Sonderleistungen | G9: =INDEX(tbl_GOAE_Leistungsverzeichnis[Unterabschnitt (Kategorie)],MATCH(Tabelle5[[#This Row],[GOÄ Nummer]],tbl_GOAE_Leistungsverzeichnis[Mapping ID],0)) -> I. Anlegen von Verbänden | H9: =INDEX(tbl_GOAE_Leistungsverzeichnis[Nummer],MATCH(Tabelle5[[#This Row],[GOÄ Nummer]],tbl_GOAE_Leistungsverzeichnis[Mapping ID],0)) -> 201 | I9: =INDEX(tbl_GOAE_Leistungsverzeichnis[Allgemeine Bestimmungen],MATCH(Tabelle5[[#This Row],[GOÄ Nummer]],tbl_GOAE_Leistungsverzeichnis[Mapping ID],0)) -> Wundverbände nach Nummer 200, die im Zusammenhang mit einer operativen Leistung (auch Ätzung, Fremdkörperentfernung), Punktion, Infusion, Transfusion oder Injektion durchgeführt werden, sind Bestandteil dieser Leistung.
A10: 204 | B10: Zirkulärer Verband, Rucksack oder Desault-Verband | C10: 9 | D10: Min. / Patient | E10: =INDEX(tbl_GOAE_Leistungsverzeichnis[Leistung],MATCH(Tabelle5[[#This Row],[GOÄ Nummer]],tbl_GOAE_Leistungsverzeichnis[Mapping ID],0)) -> Zirkulärer Verband des Kopfes oder des Rumpfes (auch als Wundverband); stabilisierender Verband des Halses, des Schulter- oder Hüftgelenks oder einer Extremität über mindestens zwei große Gelenke; Schanz'scher Halskrawattenverband; Kompressionsverband | F10: =INDEX(tbl_GOAE_Leistungsverzeichnis[Abschnitt],MATCH(Tabelle5[[#This Row],[GOÄ Nummer]],tbl_GOAE_Leistungsverzeichnis[Mapping ID],0)) -> C. Nichtgebietsbezogene Sonderleistungen | G10: =INDEX(tbl_GOAE_Leistungsverzeichnis[Unterabschnitt (Kategorie)],MATCH(Tabelle5[[#This Row],[GOÄ Nummer]],tbl_GOAE_Leistungsverzeichnis[Mapping ID],0)) -> I. Anlegen von Verbänden | H10: =INDEX(tbl_GOAE_Leistungsverzeichnis[Nummer],MATCH(Tabelle5[[#This Row],[GOÄ Nummer]],tbl_GOAE_Leistungsverzeichnis[Mapping ID],0)) -> 204 | I10: =INDEX(tbl_GOAE_Leistungsverzeichnis[Allgemeine Bestimmungen],MATCH(Tabelle5[[#This Row],[GOÄ Nummer]],tbl_GOAE_Leistungsverzeichnis[Mapping ID],0)) -> Wundverbände nach Nummer 200, die im Zusammenhang mit einer operativen Leistung (auch Ätzung, Fremdkörperentfernung), Punktion, Infusion, Transfusion oder Injektion durchgeführt werden, sind Bestandteil dieser Leistung.
A11: 206 | B11: Tapeverband eines kleinen Gelenks | C11: 6 | D11: Min. / Patient | E11: =INDEX(tbl_GOAE_Leistungsverzeichnis[Leistung],MATCH(Tabelle5[[#This Row],[GOÄ Nummer]],tbl_GOAE_Leistungsverzeichnis[Mapping ID],0)) -> Tape-Verband eines kleinen Gelenks | F11: =INDEX(tbl_GOAE_Leistungsverzeichnis[Abschnitt],MATCH(Tabelle5[[#This Row],[GOÄ Nummer]],tbl_GOAE_Leistungsverzeichnis[Mapping ID],0)) -> C. Nichtgebietsbezogene Sonderleistungen | G11: =INDEX(tbl_GOAE_Leistungsverzeichnis[Unterabschnitt (Kategorie)],MATCH(Tabelle5[[#This Row],[GOÄ Nummer]],tbl_GOAE_Leistungsverzeichnis[Mapping ID],0)) -> I. Anlegen von Verbänden | H11: =INDEX(tbl_GOAE_Leistungsverzeichnis[Nummer],MATCH(Tabelle5[[#This Row],[GOÄ Nummer]],tbl_GOAE_Leistungsverzeichnis[Mapping ID],0)) -> 206 | I11: =INDEX(tbl_GOAE_Leistungsverzeichnis[Allgemeine Bestimmungen],MATCH(Tabelle5[[#This Row],[GOÄ Nummer]],tbl_GOAE_Leistungsverzeichnis[Mapping ID],0)) -> Wundverbände nach Nummer 200, die im Zusammenhang mit einer operativen Leistung (auch Ätzung, Fremdkörperentfernung), Punktion, Infusion, Transfusion oder Injektion durchgeführt werden, sind Bestandteil dieser Leistung.
A12: 206 | B12: Tapeverband eines kleinen Gelenks | C12: 5 | D12: Min. / Patient | E12: =INDEX(tbl_GOAE_Leistungsverzeichnis[Leistung],MATCH(Tabelle5[[#This Row],[GOÄ Nummer]],tbl_GOAE_Leistungsverzeichnis[Mapping ID],0)) -> Tape-Verband eines kleinen Gelenks | F12: =INDEX(tbl_GOAE_Leistungsverzeichnis[Abschnitt],MATCH(Tabelle5[[#This Row],[GOÄ Nummer]],tbl_GOAE_Leistungsverzeichnis[Mapping ID],0)) -> C. Nichtgebietsbezogene Sonderleistungen | G12: =INDEX(tbl_GOAE_Leistungsverzeichnis[Unterabschnitt (Kategorie)],MATCH(Tabelle5[[#This Row],[GOÄ Nummer]],tbl_GOAE_Leistungsverzeichnis[Mapping ID],0)) -> I. Anlegen von Verbänden | H12: =INDEX(tbl_GOAE_Leistungsverzeichnis[Nummer],MATCH(Tabelle5[[#This Row],[GOÄ Nummer]],tbl_GOAE_Leistungsverzeichnis[Mapping ID],0)) -> 206 | I12: =INDEX(tbl_GOAE_Leistungsverzeichnis[Allgemeine Bestimmungen],MATCH(Tabelle5[[#This Row],[GOÄ Nummer]],tbl_GOAE_Leistungsverzeichnis[Mapping ID],0)) -> Wundverbände nach Nummer 200, die im Zusammenhang mit einer operativen Leistung (auch Ätzung, Fremdkörperentfernung), Punktion, Infusion, Transfusion oder Injektion durchgeführt werden, sind Bestandteil dieser Leistung.
A13: 207 | B13: Tapeverband eines großen Gelenks | C13: 9 | D13: Min. / Patient | E13: =INDEX(tbl_GOAE_Leistungsverzeichnis[Leistung],MATCH(Tabelle5[[#This Row],[GOÄ Nummer]],tbl_GOAE_Leistungsverzeichnis[Mapping ID],0)) -> Tape-Verband eines großen Gelenks oder Zinkleimverband | F13: =INDEX(tbl_GOAE_Leistungsverzeichnis[Abschnitt],MATCH(Tabelle5[[#This Row],[GOÄ Nummer]],tbl_GOAE_Leistungsverzeichnis[Mapping ID],0)) -> C. Nichtgebietsbezogene Sonderleistungen | G13: =INDEX(tbl_GOAE_Leistungsverzeichnis[Unterabschnitt (Kategorie)],MATCH(Tabelle5[[#This Row],[GOÄ Nummer]],tbl_GOAE_Leistungsverzeichnis[Mapping ID],0)) -> I. Anlegen von Verbänden | H13: =INDEX(tbl_GOAE_Leistungsverzeichnis[Nummer],MATCH(Tabelle5[[#This Row],[GOÄ Nummer]],tbl_GOAE_Leistungsverzeichnis[Mapping ID],0)) -> 207 | I13: =INDEX(tbl_GOAE_Leistungsverzeichnis[Allgemeine Bestimmungen],MATCH(Tabelle5[[#This Row],[GOÄ Nummer]],tbl_GOAE_Leistungsverzeichnis[Mapping ID],0)) -> Wundverbände nach Nummer 200, die im Zusammenhang mit einer operativen Leistung (auch Ätzung, Fremdkörperentfernung), Punktion, Infusion, Transfusion oder Injektion durchgeführt werden, sind Bestandteil dieser Leistung.
... A430: 5733 | B430: MRT Zuschlag für Computergestützte Analyse (z.B. Kinetik, 3D-Rekon- struktion) | C430: 8 | D430: Min. / Patient | E430: =INDEX(tbl_GOAE_Leistungsverzeichnis[Leistung],MATCH(Tabelle5[[#This Row],[GOÄ Nummer]],tbl_GOAE_Leistungsverzeichnis[Mapping ID],0)) -> Zuschlag für computergesteuerte Analyse (z.B. Kinetik, 3D-Rekonstruktion) | F430: =INDEX(tbl_GOAE_Leistungsverzeichnis[Abschnitt],MATCH(Tabelle5[[#This Row],[GOÄ Nummer]],tbl_GOAE_Leistungsverzeichnis[Mapping ID],0)) -> O. Strahlendiagnostik, Nuklearmedizin, Magnetresonanztomographie und Strahlentherapie | G430: =INDEX(tbl_GOAE_Leistungsverzeichnis[Unterabschnitt (Kategorie)],MATCH(Tabelle5[[#This Row],[GOÄ Nummer]],tbl_GOAE_Leistungsverzeichnis[Mapping ID],0)) -> 0 | H430: =INDEX(tbl_GOAE_Leistungsverzeichnis[Nummer],MATCH(Tabelle5[[#This Row],[GOÄ Nummer]],tbl_GOAE_Leistungsverzeichnis[Mapping ID],0)) -> 5733 | I430: =INDEX(tbl_GOAE_Leistungsverzeichnis[Allgemeine Bestimmungen],MATCH(Tabelle5[[#This Row],[GOÄ Nummer]],tbl_GOAE_Leistungsverzeichnis[Mapping ID],0)) -> Die Leistungen nach den Nummern 5700 bis 5735 sind je Sitzung jeweils nur einmal berechnungsfähig. Die Nebeneinanderberechnung von Leistungen nach den Nummern 5700 bis 5730 ist in der Rechnung besonders zu begründen. Bei Nebeneinanderberechnung von Leistungen nach den Nummern 5700 bis 5730 ist der Höchstwert nach Nummer 5735 zu beachten.
A431: 200a | B431: Kleiner einfacher Verband | C431: 3 | D431: Min. / Patient | E431: =INDEX(tbl_GOAE_Leistungsverzeichnis[Leistung],MATCH(Tabelle5[[#This Row],[GOÄ Nummer]],tbl_GOAE_Leistungsverzeichnis[Mapping ID],0)) -> #N/A | F431: =INDEX(tbl_GOAE_Leistungsverzeichnis[Abschnitt],MATCH(Tabelle5[[#This Row],[GOÄ Nummer]],tbl_GOAE_Leistungsverzeichnis[Mapping ID],0)) -> #N/A | G431: =INDEX(tbl_GOAE_Leistungsverzeichnis[Unterabschnitt (Kategorie)],MATCH(Tabelle5[[#This Row],[GOÄ Nummer]],tbl_GOAE_Leistungsverzeichnis[Mapping ID],0)) -> #N/A | H431: =INDEX(tbl_GOAE_Leistungsverzeichnis[Nummer],MATCH(Tabelle5[[#This Row],[GOÄ Nummer]],tbl_GOAE_Leistungsverzeichnis[Mapping ID],0)) -> #N/A | I431: =INDEX(tbl_GOAE_Leistungsverzeichnis[Allgemeine Bestimmungen],MATCH(Tabelle5[[#This Row],[GOÄ Nummer]],tbl_GOAE_Leistungsverzeichnis[Mapping ID],0)) -> #N/A
A432: 200b | B432: Großer oder schwieriger Verband | C432: 20 | D432: Min. / Patient | E432: =INDEX(tbl_GOAE_Leistungsverzeichnis[Leistung],MATCH(Tabelle5[[#This Row],[GOÄ Nummer]],tbl_GOAE_Leistungsverzeichnis[Mapping ID],0)) -> #N/A | F432: =INDEX(tbl_GOAE_Leistungsverzeichnis[Abschnitt],MATCH(Tabelle5[[#This Row],[GOÄ Nummer]],tbl_GOAE_Leistungsverzeichnis[Mapping ID],0)) -> #N/A | G432: =INDEX(tbl_GOAE_Leistungsverzeichnis[Unterabschnitt (Kategorie)],MATCH(Tabelle5[[#This Row],[GOÄ Nummer]],tbl_GOAE_Leistungsverzeichnis[Mapping ID],0)) -> #N/A | H432: =INDEX(tbl_GOAE_Leistungsverzeichnis[Nummer],MATCH(Tabelle5[[#This Row],[GOÄ Nummer]],tbl_GOAE_Leistungsverzeichnis[Mapping ID],0)) -> #N/A | I432: =INDEX(tbl_GOAE_Leistungsverzeichnis[Allgemeine Bestimmungen],MATCH(Tabelle5[[#This Row],[GOÄ Nummer]],tbl_GOAE_Leistungsverzeichnis[Mapping ID],0)) -> #N/A
A433: 200c | B433: Binokulus Verband | C433: 3 | D433: Min. / Patient | E433: =INDEX(tbl_GOAE_Leistungsverzeichnis[Leistung],MATCH(Tabelle5[[#This Row],[GOÄ Nummer]],tbl_GOAE_Leistungsverzeichnis[Mapping ID],0)) -> #N/A | F433: =INDEX(tbl_GOAE_Leistungsverzeichnis[Abschnitt],MATCH(Tabelle5[[#This Row],[GOÄ Nummer]],tbl_GOAE_Leistungsverzeichnis[Mapping ID],0)) -> #N/A | G433: =INDEX(tbl_GOAE_Leistungsverzeichnis[Unterabschnitt (Kategorie)],MATCH(Tabelle5[[#This Row],[GOÄ Nummer]],tbl_GOAE_Leistungsverzeichnis[Mapping ID],0)) -> #N/A | H433: =INDEX(tbl_GOAE_Leistungsverzeichnis[Nummer],MATCH(Tabelle5[[#This Row],[GOÄ Nummer]],tbl_GOAE_Leistungsverzeichnis[Mapping ID],0)) -> #N/A | I433: =INDEX(tbl_GOAE_Leistungsverzeichnis[Allgemeine Bestimmungen],MATCH(Tabelle5[[#This Row],[GOÄ Nummer]],tbl_GOAE_Leistungsverzeichnis[Mapping ID],0)) -> #N/A
A434: 200d | B434: Anlegen einer elastischen Binde an einer Extremität | C434: 3 | D434: Min. / Patient | E434: =INDEX(tbl_GOAE_Leistungsverzeichnis[Leistung],MATCH(Tabelle5[[#This Row],[GOÄ Nummer]],tbl_GOAE_Leistungsverzeichnis[Mapping ID],0)) -> #N/A | F434: =INDEX(tbl_GOAE_Leistungsverzeichnis[Abschnitt],MATCH(Tabelle5[[#This Row],[GOÄ Nummer]],tbl_GOAE_Leistungsverzeichnis[Mapping ID],0)) -> #N/A | G434: =INDEX(tbl_GOAE_Leistungsverzeichnis[Unterabschnitt (Kategorie)],MATCH(Tabelle5[[#This Row],[GOÄ Nummer]],tbl_GOAE_Leistungsverzeichnis[Mapping ID],0)) -> #N/A | H434: =INDEX(tbl_GOAE_Leistungsverzeichnis[Nummer],MATCH(Tabelle5[[#This Row],[GOÄ Nummer]],tbl_GOAE_Leistungsverzeichnis[Mapping ID],0)) -> #N/A | I434: =INDEX(tbl_GOAE_Leistungsverzeichnis[Allgemeine Bestimmungen],MATCH(Tabelle5[[#This Row],[GOÄ Nummer]],tbl_GOAE_Leistungsverzeichnis[Mapping ID],0)) -> #N/A
A435: 200e | B435: Anlegen einer redressierenden Kleb-Binde an Hand und/oder Arm | C435: 3 | D435: Min. / Patient | E435: =INDEX(tbl_GOAE_Leistungsverzeichnis[Leistung],MATCH(Tabelle5[[#This Row],[GOÄ Nummer]],tbl_GOAE_Leistungsverzeichnis[Mapping ID],0)) -> #N/A | F435: =INDEX(tbl_GOAE_Leistungsverzeichnis[Abschnitt],MATCH(Tabelle5[[#This Row],[GOÄ Nummer]],tbl_GOAE_Leistungsverzeichnis[Mapping ID],0)) -> #N/A | G435: =INDEX(tbl_GOAE_Leistungsverzeichnis[Unterabschnitt (Kategorie)],MATCH(Tabelle5[[#This Row],[GOÄ Nummer]],tbl_GOAE_Leistungsverzeichnis[Mapping ID],0)) -> #N/A | H435: =INDEX(tbl_GOAE_Leistungsverzeichnis[Nummer],MATCH(Tabelle5[[#This Row],[GOÄ Nummer]],tbl_GOAE_Leistungsverzeichnis[Mapping ID],0)) -> #N/A | I435: =INDEX(tbl_GOAE_Leistungsverzeichnis[Allgemeine Bestimmungen],MATCH(Tabelle5[[#This Row],[GOÄ Nummer]],tbl_GOAE_Leistungsverzeichnis[Mapping ID],0)) -> #N/A
A436: 200f | B436: Anlegen einer Gummi-Elastik-Binde an einer Extremität | C436: 3 | D436: Min. / Patient | E436: =INDEX(tbl_GOAE_Leistungsverzeichnis[Leistung],MATCH(Tabelle5[[#This Row],[GOÄ Nummer]],tbl_GOAE_Leistungsverzeichnis[Mapping ID],0)) -> #N/A | F436: =INDEX(tbl_GOAE_Leistungsverzeichnis[Abschnitt],MATCH(Tabelle5[[#This Row],[GOÄ Nummer]],tbl_GOAE_Leistungsverzeichnis[Mapping ID],0)) -> #N/A | G436: =INDEX(tbl_GOAE_Leistungsverzeichnis[Unterabschnitt (Kategorie)],MATCH(Tabelle5[[#This Row],[GOÄ Nummer]],tbl_GOAE_Leistungsverzeichnis[Mapping ID],0)) -> #N/A | H436: =INDEX(tbl_GOAE_Leistungsverzeichnis[Nummer],MATCH(Tabelle5[[#This Row],[GOÄ Nummer]],tbl_GOAE_Leistungsverzeichnis[Mapping ID],0)) -> #N/A | I436: =INDEX(tbl_GOAE_Leistungsverzeichnis[Allgemeine Bestimmungen],MATCH(Tabelle5[[#This Row],[GOÄ Nummer]],tbl_GOAE_Leistungsverzeichnis[Mapping ID],0)) -> #N/A
A437: 200g | B437: Anlegen eines redressierenden Kleb-Verbandes an den Fuß und/oder Bein | C437: 3 | D437: Min. / Patient | E437: =INDEX(tbl_GOAE_Leistungsverzeichnis[Leistung],MATCH(Tabelle5[[#This Row],[GOÄ Nummer]],tbl_GOAE_Leistungsverzeichnis[Mapping ID],0)) -> #N/A | F437: =INDEX(tbl_GOAE_Leistungsverzeichnis[Abschnitt],MATCH(Tabelle5[[#This Row],[GOÄ Nummer]],tbl_GOAE_Leistungsverzeichnis[Mapping ID],0)) -> #N/A | G437: =INDEX(tbl_GOAE_Leistungsverzeichnis[Unterabschnitt (Kategorie)],MATCH(Tabelle5[[#This Row],[GOÄ Nummer]],tbl_GOAE_Leistungsverzeichnis[Mapping ID],0)) -> #N/A | H437: =INDEX(tbl_GOAE_Leistungsverzeichnis[Nummer],MATCH(Tabelle5[[#This Row],[GOÄ Nummer]],tbl_GOAE_Leistungsverzeichnis[Mapping ID],0)) -> #N/A | I437: =INDEX(tbl_GOAE_Leistungsverzeichnis[Allgemeine Bestimmungen],MATCH(Tabelle5[[#This Row],[GOÄ Nummer]],tbl_GOAE_Leistungsverzeichnis[Mapping ID],0)) -> #N/A
A438: 201a | B438: Redressierender Klebeverband des Brustkorbs oder dachziegelförmiger Klebeverband als TAPE-Verband | C438: 6 | D438: Min. / Patient | E438: =INDEX(tbl_GOAE_Leistungsverzeichnis[Leistung],MATCH(Tabelle5[[#This Row],[GOÄ Nummer]],tbl_GOAE_Leistungsverzeichnis[Mapping ID],0)) -> #N/A | F438: =INDEX(tbl_GOAE_Leistungsverzeichnis[Abschnitt],MATCH(Tabelle5[[#This Row],[GOÄ Nummer]],tbl_GOAE_Leistungsverzeichnis[Mapping ID],0)) -> #N/A | G438: =INDEX(tbl_GOAE_Leistungsverzeichnis[Unterabschnitt (Kategorie)],MATCH(Tabelle5[[#This Row],[GOÄ Nummer]],tbl_GOAE_Leistungsverzeichnis[Mapping ID],0)) -> #N/A | H438: =INDEX(tbl_GOAE_Leistungsverzeichnis[Nummer],MATCH(Tabelle5[[#This Row],[GOÄ Nummer]],tbl_GOAE_Leistungsverzeichnis[Mapping ID],0)) -> #N/A | I438: =INDEX(tbl_GOAE_Leistungsverzeichnis[Allgemeine Bestimmungen],MATCH(Tabelle5[[#This Row],[GOÄ Nummer]],tbl_GOAE_Leistungsverzeichnis[Mapping ID],0)) -> #N/A
A439: 207a | B439: Tape-Verband eines großen Gelenks oder Zinkleimverband | C439: 9 | D439: Min. / Patient | E439: =INDEX(tbl_GOAE_Leistungsverzeichnis[Leistung],MATCH(Tabelle5[[#This Row],[GOÄ Nummer]],tbl_GOAE_Leistungsverzeichnis[Mapping ID],0)) -> #N/A | F439: =INDEX(tbl_GOAE_Leistungsverzeichnis[Abschnitt],MATCH(Tabelle5[[#This Row],[GOÄ Nummer]],tbl_GOAE_Leistungsverzeichnis[Mapping ID],0)) -> #N/A | G439: =INDEX(tbl_GOAE_Leistungsverzeichnis[Unterabschnitt (Kategorie)],MATCH(Tabelle5[[#This Row],[GOÄ Nummer]],tbl_GOAE_Leistungsverzeichnis[Mapping ID],0)) -> #N/A | H439: =INDEX(tbl_GOAE_Leistungsverzeichnis[Nummer],MATCH(Tabelle5[[#This Row],[GOÄ Nummer]],tbl_GOAE_Leistungsverzeichnis[Mapping ID],0)) -> #N/A | I439: =INDEX(tbl_GOAE_Leistungsverzeichnis[Allgemeine Bestimmungen],MATCH(Tabelle5[[#This Row],[GOÄ Nummer]],tbl_GOAE_Leistungsverzeichnis[Mapping ID],0)) -> #N/A
